Workbook
Name Slicer_Department: #N/A
Name Slicer_Joining_Month: #N/A
Name Slicer_Location: #N/A

Sheet Dashboard
G8: =Findings!H8&" "

Sheet Findings
F1: Key Insights | G1: Value
A2: Attration by Department | F2: Average Attration across all departments | G2: =GETPIVOTDATA("Attration Flag",$I$29) -> 0.506
A3: Row Labels | B3: Sum of Attration Flag | F3: highest attrition | G3: =MAX(GETPIVOTDATA("Attration Flag",$I$29,"Department","Finance"),GETPIVOTDATA("Attration Flag",$I$29,"Department","HR"),GETPIVOTDATA("Attration Flag",$I$29,"Department","IT"),GETPIVOTDATA("Attration Flag",$I$29,"Department","Operations"),GETPIVOTDATA("Attration Flag",$I$29,"Department","Sales")) -> 0.55555556
A4: Finance | B4: 45 | F4: highest attrition month | G4: =VLOOKUP(MAX(GETPIVOTDATA("Attration Flag",$A$24,"Joining Month","Jan"),GETPIVOTDATA("Attration Flag",$A$24,"Joining Month","Feb"),GETPIVOTDATA("Attration Flag",$A$24,"Joining Month","Mar"),GETPIVOTDATA("Attration Flag",$A$24,"Joining Month","Apr"),GETPIVOTDATA("Attration Flag",$A$24,"Joining Month","May"),GETPIVOTDATA("Attration Flag",$A$24,"Joining Month","Jun"),GETPIVOTDATA("Attration Flag",$A$24,"Joining Month","Jul"),GETPIVOTDATA("Attration Flag",$A$24,"Joining Month","Aug"),GETPIVOTDATA("Attration Flag",$A$24,"Joining Month","Sep"),GETPIVOTDATA("Attration Flag",$A$24,"Joining Month","Oct"),GETPIVOTDATA("Attration Flag",$A$24,"Joining Month","Nov"),GETPIVOTDATA("Attration Flag",$A$24,"Joining Month","Dec")),CHOOSE({1,2},B25:B36,A25:A36),2,0) -> Jun
A5: HR | B5: 64 | F5: Attration Contribution by performance | G5: =VLOOKUP(MAX(B63:B64),CHOOSE({1,2},B63:B64,A63:A64),2,0) -> Low
A6: IT | B6: 56 | F6: Total Employees | G6: =GETPIVOTDATA("Employee_ID",$A$74) -> 500
A7: Operations | B7: 41 | F7: Currently Working | G7: =GETPIVOTDATA("Working",$A$15) -> 247
A8: Sales | B8: 47 | F8: Attration % | G8: =GETPIVOTDATA("Attration Flag",$I$29) -> 0.506
A9: Grand Total | B9: 253 | F9: Average Salary | G9: =GETPIVOTDATA("Salary",$A$77) -> 712289.96
F10: Average Attendance | G10: =GETPIVOTDATA("Attendance_%",$F$13) -> 87.303
F11: Highest Attration dept | G11: =VLOOKUP(MAX(GETPIVOTDATA("Attration Flag",$I$29,"Department","Finance"),GETPIVOTDATA("Attration Flag",$I$29,"Department","HR"),GETPIVOTDATA("Attration Flag",$I$29,"Department","IT"),GETPIVOTDATA("Attration Flag",$I$29,"Department","Operations"),GETPIVOTDATA("Attration Flag",$I$29,"Department","Sales")),CHOOSE({1,2},J30:J34,I30:I34),2,0) -> Finance
F13: Row Labels | G13: Average of Attendance_%
A14: Headcount by Department | F14: Finance | G14: 87.745679
A15: Row Labels | B15: Currently Working | F15: HR | G15: 87.5576
A16: Finance | B16: 36 | F16: IT | G16: 87.280734
A17: HR | B17: 61 | F17: Operations | G17: 86.674194
A18: IT | B18: 53 | F18: Sales | G18: 87.229348
A19: Operations | B19: 52 | F19: Grand Total | G19: 87.303
A20: Sales | B20: 45
A21: Grand Total | B21: 247 | F21: Attration % by Department
F22: Department | G22: Attration | H22: Total Employees by dept | I22: Attreation %
A23: Count of Monthly Resignation | F23: Finance | G23: =SUMIFS(Table1_1[Attration Flag],Table1_1[Department],Findings!$F23) -> 45 | H23: =COUNTIFS(Table1_1[Department],Findings!$F23) -> 81 | I23: =(G23/H23) -> 0.55555556
A24: Row Labels | B24: Candidates Resigned | F24: HR | G24: =SUMIFS(Table1_1[Attration Flag],Table1_1[Department],Findings!$F24) -> 64 | H24: =COUNTIFS(Table1_1[Department],Findings!$F24) -> 125 | I24: =(G24/H24) -> 0.512
A25: Jan | B25: 19 | F25: IT | G25: =SUMIFS(Table1_1[Attration Flag],Table1_1[Department],Findings!$F25) -> 56 | H25: =COUNTIFS(Table1_1[Department],Findings!$F25) -> 109 | I25: =(G25/H25) -> 0.51376147
A26: Feb | B26: 18 | F26: Operations | G26: =SUMIFS(Table1_1[Attration Flag],Table1_1[Department],Findings!$F26) -> 41 | H26: =COUNTIFS(Table1_1[Department],Findings!$F26) -> 93 | I26: =(G26/H26) -> 0.44086022
A27: Mar | B27: 25 | F27: Sales | G27: =SUMIFS(Table1_1[Attration Flag],Table1_1[Department],Findings!$F27) -> 47 | H27: =COUNTIFS(Table1_1[Department],Findings!$F27) -> 92 | I27: =(G27/H27) -> 0.51086957
A28: Apr | B28: 19
A29: May | B29: 24 | F29: Finance | G29: =VLOOKUP(F29,A3:B9,2,0) -> 45 | I29: Row Labels | J29: Average of Attration Flag
A30: Jun | B30: 28 | F30: HR | G30: =VLOOKUP(F30,A4:B12,2,0) -> 64 | I30: Finance | J30: 0.55555556
A31: Jul | B31: 23 | F31: IT | G31: =VLOOKUP(F31,A5:B13,2,0) -> 56 | I31: HR | J31: 0.512
A32: Aug | B32: 15 | F32: Operations | G32: =VLOOKUP(F32,A6:B14,2,0) -> 41 | I32: IT | J32: 0.51376147
A33: Sep | B33: 21 | F33: Sales | G33: =VLOOKUP(F33,A7:B15,2,0) -> 47 | I33: Operations | J33: 0.44086022
A34: Oct | B34: 18 | I34: Sales | J34: 0.51086957
A35: Nov | B35: 21 | F35: Row Labels | I35: Grand Total | J35: 0.506
A36: Dec | B36: 22 | F36: Finance
A37: Grand Total | B37: 253 | F37: HR
F38: IT
A39: Active Employees by Joining Month | F39: Operations
A40: Row Labels | B40: Joined | C40: Resigned | F40: Sales
A41: Jan | B41: 16 | C41: 19 | F41: Grand Total
...

Sheet Table1
A1: Employee_ID | B1: Name | C1: Department | D1: Designation | E1: Location | F1: Joining_Date | G1: Joining Month | H1: Year | I1: Exit_Date | J1: Status | K1: Attration Flag | L1: Working | M1: Salary | N1: Performance_Rating | O1: Manager | P1: Attendance_% | Q1: Performance Distribution | T1: Performance_Rating | X1: Attendance_%
A2: EMP0001 | B2: Employee_1 | C2: Operations | D2: Executive | E2: Pune | F2: 2018-04-19 | G2: =TEXT(Table1_1[[#This Row],[Joining_Date]],"mmm") -> Apr | H2: =TEXT(Table1_1[[#This Row],[Joining_Date]],"yyyy") -> 2018 | I2: 44523 | J2: Exited | K2: =IF(Table1_1[[#This Row],[Status]]="Exited",1,0) -> 1 | L2: =IF(Table1_1[[#This Row],[Status]]="Exited",0,1) -> 0 | M2: 1097194 | N2: 3.6 | O2: Manager D | P2: 84.8 | Q2: =IF(AND(N2>4,P2>=75),"High", IF(AND(N2>2,N2<=4,P2>40,P2<=74),"Average","Low")) -> Low | S2: =IF(AND(T2>4,X2>=75),"High", IF(AND(T2>2,T2<=4,X2>40,X2<=74),"Average","Low")) -> Low | T2: 3.6 | U2: =MAX(T2:T32) -> 5 | V2: MAX | X2: 84.8 | Y2: 0-40 | Z2: low
A3: EMP0002 | B3: Employee_2 | C3: IT | D3: Manager | E3: Pune | F3: 2023-09-07 | G3: =TEXT(Table1_1[[#This Row],[Joining_Date]],"mmm") -> Sep | H3: =TEXT(Table1_1[[#This Row],[Joining_Date]],"yyyy") -> 2023 | I3: 46056 | J3: Exited | K3: =IF(Table1_1[[#This Row],[Status]]="Exited",1,0) -> 1 | L3: =IF(Table1_1[[#This Row],[Status]]="Exited",0,1) -> 0 | M3: 269845 | N3: 3.6 | O3: Manager B | P3: 91.2 | Q3: =IF(AND(N3>4,P3>=75),"High", IF(AND(N3>2,N3<=4,P3>40,P3<=74),"Average","Low")) -> Low | T3: 2.4 | U3: =MIN(T2:T32) -> 2 | V3: MIN | X3: 91.2 | Y3: 41-75 | Z3: Average
A4: EMP0003 | B4: Employee_3 | C4: Operations | D4: Executive | E4: Bangalore | F4: 2020-07-16 | G4: =TEXT(Table1_1[[#This Row],[Joining_Date]],"mmm") -> Jul | H4: =TEXT(Table1_1[[#This Row],[Joining_Date]],"yyyy") -> 2020 | J4: Active | K4: =IF(Table1_1[[#This Row],[Status]]="Exited",1,0) -> 0 | L4: =IF(Table1_1[[#This Row],[Status]]="Exited",0,1) -> 1 | M4: 940921 | N4: 2.4 | O4: Manager A | P4: 81.1 | Q4: =IF(AND(N4>4,P4>=75),"High", IF(AND(N4>2,N4<=4,P4>40,P4<=74),"Average","Low")) -> Low | T4: 4.9 | V4: MID | X4: 81.1 | Y4: >75 | Z4: High
A5: EMP0004 | B5: Employee_4 | C5: IT | D5: Analyst | E5: Bangalore | F5: 2018-06-05 | G5: =TEXT(Table1_1[[#This Row],[Joining_Date]],"mmm") -> Jun | H5: =TEXT(Table1_1[[#This Row],[Joining_Date]],"yyyy") -> 2018 | J5: Active | K5: =IF(Table1_1[[#This Row],[Status]]="Exited",1,0) -> 0 | L5: =IF(Table1_1[[#This Row],[Status]]="Exited",0,1) -> 1 | M5: 776143 | N5: 4.9 | O5: Manager A | P5: 81.9 | Q5: =IF(AND(N5>4,P5>=75),"High", IF(AND(N5>2,N5<=4,P5>40,P5<=74),"Average","Low")) -> High | T5: 4.7 | X5: 81.9
A6: EMP0005 | B6: Employee_5 | C6: Sales | D6: Analyst | E6: Bangalore | F6: 2018-04-22 | G6: =TEXT(Table1_1[[#This Row],[Joining_Date]],"mmm") -> Apr | H6: =TEXT(Table1_1[[#This Row],[Joining_Date]],"yyyy") -> 2018 | J6: Active | K6: =IF(Table1_1[[#This Row],[Status]]="Exited",1,0) -> 0 | L6: =IF(Table1_1[[#This Row],[Status]]="Exited",0,1) -> 1 | M6: 257947 | N6: 4.7 | O6: Manager A | P6: 82 | Q6: =IF(AND(N6>4,P6>=75),"High", IF(AND(N6>2,N6<=4,P6>40,P6<=74),"Average","Low")) -> High | T6: 3.3 | X6: 82
A7: EMP0006 | B7: Employee_6 | C7: Sales | D7: Executive | E7: Bangalore | F7: 2024-08-02 | G7: =TEXT(Table1_1[[#This Row],[Joining_Date]],"mmm") -> Aug | H7: =TEXT(Table1_1[[#This Row],[Joining_Date]],"yyyy") -> 2024 | J7: Active | K7: =IF(Table1_1[[#This Row],[Status]]="Exited",1,0) -> 0 | L7: =IF(Table1_1[[#This Row],[Status]]="Exited",0,1) -> 1 | M7: 566222 | N7: 3.3 | O7: Manager C | P7: 75 | Q7: =IF(AND(N7>4,P7>=75),"High", IF(AND(N7>2,N7<=4,P7>40,P7<=74),"Average","Low")) -> Low | T7: 2.9 | X7: 75
A8: EMP0007 | B8: Employee_7 | C8: Sales | D8: Manager | E8: Mumbai | F8: 2023-09-14 | G8: =TEXT(Table1_1[[#This Row],[Joining_Date]],"mmm") -> Sep | H8: =TEXT(Table1_1[[#This Row],[Joining_Date]],"yyyy") -> 2023 | I8: 45884 | J8: Exited | K8: =IF(Table1_1[[#This Row],[Status]]="Exited",1,0) -> 1 | L8: =IF(Table1_1[[#This Row],[Status]]="Exited",0,1) -> 0 | M8: 1069012 | N8: 2.9 | O8: Manager C | P8: 86.3 | Q8: =IF(AND(N8>4,P8>=75),"High", IF(AND(N8>2,N8<=4,P8>40,P8<=74),"Average","Low")) -> Low | T8: 3.7 | X8: 86.3
A9: EMP0008 | B9: Employee_8 | C9: IT | D9: Senior Executive | E9: Nagpur | F9: 2018-09-02 | G9: =TEXT(Table1_1[[#This Row],[Joining_Date]],"mmm") -> Sep | H9: =TEXT(Table1_1[[#This Row],[Joining_Date]],"yyyy") -> 2018 | J9: Active | K9: =IF(Table1_1[[#This Row],[Status]]="Exited",1,0) -> 0 | L9: =IF(Table1_1[[#This Row],[Status]]="Exited",0,1) -> 1 | M9: 920186 | N9: 3.7 | O9: Manager A | P9: 87.1 | Q9: =IF(AND(N9>4,P9>=75),"High", IF(AND(N9>2,N9<=4,P9>40,P9<=74),"Average","Low")) -> Low | T9: 4.8 | X9: 87.1
A10: EMP0009 | B10: Employee_9 | C10: HR | D10: Analyst | E10: Pune | F10: 2019-12-15 | G10: =TEXT(Table1_1[[#This Row],[Joining_Date]],"mmm") -> Dec | H10: =TEXT(Table1_1[[#This Row],[Joining_Date]],"yyyy") -> 2019 | J10: Active | K10: =IF(Table1_1[[#This Row],[Status]]="Exited",1,0) -> 0 | L10: =IF(Table1_1[[#This Row],[Status]]="Exited",0,1) -> 1 | M10: 731613 | N10: 4.8 | O10: Manager A | P10: 85.8 | Q10: =IF(AND(N10>4,P10>=75),"High", IF(AND(N10>2,N10<=4,P10>40,P10<=74),"Average","Low")) -> High | T10: 3.5 | X10: 85.8
A11: EMP0010 | B11: Employee_10 | C11: Sales | D11: Senior Executive | E11: Bangalore | F11: 2019-02-15 | G11: =TEXT(Table1_1[[#This Row],[Joining_Date]],"mmm") -> Feb | H11: =TEXT(Table1_1[[#This Row],[Joining_Date]],"yyyy") -> 2019 | J11: Active | K11: =IF(Table1_1[[#This Row],[Status]]="Exited",1,0) -> 0 | L11: =IF(Table1_1[[#This Row],[Status]]="Exited",0,1) -> 1 | M11: 714786 | N11: 4.9 | O11: Manager C | P11: 76.4 | Q11: =IF(AND(N11>4,P11>=75),"High", IF(AND(N11>2,N11<=4,P11>40,P11<=74),"Average","Low")) -> High | T11: 3.2 | X11: 76.4
A12: EMP0011 | B12: Employee_11 | C12: Finance | D12: Senior Executive | E12: Bangalore | F12: 2018-09-18 | G12: =TEXT(Table1_1[[#This Row],[Joining_Date]],"mmm") -> Sep | H12: =TEXT(Table1_1[[#This Row],[Joining_Date]],"yyyy") -> 2018 | J12: Active | K12: =IF(Table1_1[[#This Row],[Status]]="Exited",1,0) -> 0 | L12: =IF(Table1_1[[#This Row],[Status]]="Exited",0,1) -> 1 | M12: 771857 | N12: 3.5 | O12: Manager C | P12: 84.2 | Q12: =IF(AND(N12>4,P12>=75),"High", IF(AND(N12>2,N12<=4,P12>40,P12<=74),"Average","Low")) -> Low | T12: 2.5 | X12: 84.2
A13: EMP0012 | B13: Employee_12 | C13: IT | D13: Analyst | E13: Mumbai | F13: 2018-10-24 | G13: =TEXT(Table1_1[[#This Row],[Joining_Date]],"mmm") -> Oct | H13: =TEXT(Table1_1[[#This Row],[Joining_Date]],"yyyy") -> 2018 | J13: Active | K13: =IF(Table1_1[[#This Row],[Status]]="Exited",1,0) -> 0 | L13: =IF(Table1_1[[#This Row],[Status]]="Exited",0,1) -> 1 | M13: 1017999 | N13: 2.4 | O13: Manager C | P13: 87.6 | Q13: =IF(AND(N13>4,P13>=75),"High", IF(AND(N13>2,N13<=4,P13>40,P13<=74),"Average","Low")) -> Low | T13: 3.4 | X13: 87.6
A14: EMP0013 | B14: Employee_13 | C14: Operations | D14: Senior Executive | E14: Nagpur | F14: 2019-03-29 | G14: =TEXT(Table1_1[[#This Row],[Joining_Date]],"mmm") -> Mar | H14: =TEXT(Table1_1[[#This Row],[Joining_Date]],"yyyy") -> 2019 | J14: Active | K14: =IF(Table1_1[[#This Row],[Status]]="Exited",1,0) -> 0 | L14: =IF(Table1_1[[#This Row],[Status]]="Exited",0,1) -> 1 | M14: 220169 | N14: 3.3 | O14: Manager C | P14: 77.7 | Q14: =IF(AND(N14>4,P14>=75),"High", IF(AND(N14>2,N14<=4,P14>40,P14<=74),"Average","Low")) -> Low | T14: 4.6 | X14: 77.7
A15: EMP0014 | B15: Employee_14 | C15: Operations | D15: Senior Executive | E15: Bangalore | F15: 2022-03-23 | G15: =TEXT(Table1_1[[#This Row],[Joining_Date]],"mmm") -> Mar | H15: =TEXT(Table1_1[[#This Row],[Joining_Date]],"yyyy") -> 2022 | I15: 45880 | J15: Exited | K15: =IF(Table1_1[[#This Row],[Status]]="Exited",1,0) -> 1 | L15: =IF(Table1_1[[#This Row],[Status]]="Exited",0,1) -> 0 | M15: 315950 | N15: 3.2 | O15: Manager D | P15: 95.4 | Q15: =IF(AND(N15>4,P15>=75),"High", IF(AND(N15>2,N15<=4,P15>40,P15<=74),"Average","Low")) -> Low | T15: 2.1 | X15: 95.4
A16: EMP0015 | B16: Employee_15 | C16: IT | D16: Manager | E16: Bangalore | F16: 2018-12-13 | G16: =TEXT(Table1_1[[#This Row],[Joining_Date]],"mmm") -> Dec | H16: =TEXT(Table1_1[[#This Row],[Joining_Date]],"yyyy") -> 2018 | J16: Active | K16: =IF(Table1_1[[#This Row],[Status]]="Exited",1,0) -> 0 | L16: =IF(Table1_1[[#This Row],[Status]]="Exited",0,1) -> 1 | M16: 1045488 | N16: 2.5 | O16: Manager C | P16: 91.4 | Q16: =IF(AND(N16>4,P16>=75),"High", IF(AND(N16>2,N16<=4,P16>40,P16<=74),"Average","Low")) -> Low | T16: 4.4 | X16: 91.4
A17: EMP0016 | B17: Employee_16 | C17: Finance | D17: Senior Executive | E17: Pune | F17: 2018-07-15 | G17: =TEXT(Table1_1[[#This Row],[Joining_Date]],"mmm") -> Jul | H17: =TEXT(Table1_1[[#This Row],[Joining_Date]],"yyyy") -> 2018 | J17: Active | K17: =IF(Table1_1[[#This Row],[Status]]="Exited",1,0) -> 0 | L17: =IF(Table1_1[[#This Row],[Status]]="Exited",0,1) -> 1 | M17: 786178 | N17: 3.5 | O17: Manager C | P17: 77.4 | Q17: =IF(AND(N17>4,P17>=75),"High", IF(AND(N17>2,N17<=4,P17>40,P17<=74),"Average","Low")) -> Low | T17: 2.7 | X17: 77.4
A18: EMP0017 | B18: Employee_17 | C18: Finance | D18: Senior Executive | E18: Bangalore | F18: 2024-05-01 | G18: =TEXT(Table1_1[[#This Row],[Joining_Date]],"mmm") -> May | H18: =TEXT(Table1_1[[#This Row],[Joining_Date]],"yyyy") -> 2024 | I18: 46876 | J18: Exited | K18: =IF(Table1_1[[#This Row],[Status]]="Exited",1,0) -> 1 | L18: =IF(Table1_1[[#This Row],[Status]]="Exited",0,1) -> 0 | M18: 515475 | N18: 3.5 | O18: Manager B | P18: 83.8 | Q18: =IF(AND(N18>4,P18>=75),"High", IF(AND(N18>2,N18<=4,P18>40,P18<=74),"Average","Low")) -> Low | T18: 4.5 | X18: 83.8
A19: EMP0018 | B19: Employee_18 | C19: IT | D19: Senior Executive | E19: Pune | F19: 2021-12-18 | G19: =TEXT(Table1_1[[#This Row],[Joining_Date]],"mmm") -> Dec | H19: =TEXT(Table1_1[[#This Row],[Joining_Date]],"yyyy") -> 2021 | I19: 45043 | J19: Exited | K19: =IF(Table1_1[[#This Row],[Status]]="Exited",1,0) -> 1 | L19: =IF(Table1_1[[#This Row],[Status]]="Exited",0,1) -> 0 | M19: 403143 | N19: 3.4 | O19: Manager C | P19: 75.1 | Q19: =IF(AND(N19>4,P19>=75),"High", IF(AND(N19>2,N19<=4,P19>40,P19<=74),"Average","Low")) -> Low | T19: 2.2 | X19: 75.1
A20: EMP0019 | B20: Employee_19 | C20: IT | D20: Executive | E20: Pune | F20: 2019-05-11 | G20: =TEXT(Table1_1[[#This Row],[Joining_Date]],"mmm") -> May | H20: =TEXT(Table1_1[[#This Row],[Joining_Date]],"yyyy") -> 2019 | I20: 43841 | J20: Exited | K20: =IF(Table1_1[[#This Row],[Status]]="Exited",1,0) -> 1 | L20: =IF(Table1_1[[#This Row],[Status]]="Exited",0,1) -> 0 | M20: 475080 | N20: 4.6 | O20: Manager C | P20: 97.8 | Q20: =IF(AND(N20>4,P20>=75),"High", IF(AND(N20>2,N20<=4,P20>40,P20<=74),"Average","Low")) -> High | T20: 3.9 | X20: 97.8
A21: EMP0020 | B21: Employee_20 | C21: HR | D21: Manager | E21: Bangalore | F21: 2018-09-01 | G21: =TEXT(Table1_1[[#This Row],[Joining_Date]],"mmm") -> Sep | H21: =TEXT(Table1_1[[#This Row],[Joining_Date]],"yyyy") -> 2018 | I21: 44654 | J21: Exited | K21: =IF(Table1_1[[#This Row],[Status]]="Exited",1,0) -> 1 | L21: =IF(Table1_1[[#This Row],[Status]]="Exited",0,1) -> 0 | M21: 338549 | N21: 2.1 | O21: Manager A | P21: 79.9 | Q21: =IF(AND(N21>4,P21>=75),"High", IF(AND(N21>2,N21<=4,P21>40,P21<=74),"Average","Low")) -> Low | T21: 2.3 | X21: 79.9
A22: EMP0021 | B22: Employee_21 | C22: Operations | D22: Analyst | E22: Nagpur | F22: 2024-08-20 | G22: =TEXT(Table1_1[[#This Row],[Joining_Date]],"mmm") -> Aug | H22: =TEXT(Table1_1[[#This Row],[Joining_Date]],"yyyy") -> 2024 | J22: Active | K22: =IF(Table1_1[[#This Row],[Status]]="Exited",1,0) -> 0 | L22: =IF(Table1_1[[#This Row],[Status]]="Exited",0,1) -> 1 | M22: 614309 | N22: 4.4 | O22: Manager A | P22: 79.8 | Q22: =IF(AND(N22>4,P22>=75),"High", IF(AND(N22>2,N22<=4,P22>40,P22<=74),"Average","Low")) -> High | T22: 2.8 | X22: 79.8
A23: EMP0022 | B23: Employee_22 | C23: Operations | D23: Executive | E23: Pune | F23: 2024-08-28 | G23: =TEXT(Table1_1[[#This Row],[Joining_Date]],"mmm") -> Aug | H23: =TEXT(Table1_1[[#This Row],[Joining_Date]],"yyyy") -> 2024 | J23: Active | K23: =IF(Table1_1[[#This Row],[Status]]="Exited",1,0) -> 0 | L23: =IF(Table1_1[[#This Row],[Status]]="Exited",0,1) -> 1 | M23: 893780 | N23: 2.7 | O23: Manager B | P23: 87.7 | Q23: =IF(AND(N23>4,P23>=75),"High", IF(AND(N23>2,N23<=4,P23>40,P23<=74),"Average","Low")) -> Low | T23: 5 | X23: 87.7
A24: EMP0023 | B24: Employee_23 | C24: Finance | D24: Senior Executive | E24: Mumbai | F24: 2023-01-01 | G24: =TEXT(Table1_1[[#This Row],[Joining_Date]],"mmm") -> Jan | H24: =TEXT(Table1_1[[#This Row],[Joining_Date]],"yyyy") -> 2023 | I24: 45866 | J24: Exited | K24: =IF(Table1_1[[#This Row],[Status]]="Exited",1,0) -> 1 | L24: =IF(Table1_1[[#This Row],[Status]]="Exited",0,1) -> 0 | M24: 474058 | N24: 4.5 | O24: Manager C | P24: 92.6 | Q24: =IF(AND(N24>4,P24>=75),"High", IF(AND(N24>2,N24<=4,P24>40,P24<=74),"Average","Low")) -> High | T24: 4.3 | X24: 92.6
A25: EMP0024 | B25: Employee_24 | C25: IT | D25: Executive | E25: Bangalore | F25: 2020-07-05 | G25: =TEXT(Table1_1[[#This Row],[Joining_Date]],"mmm") -> Jul | H25: =TEXT(Table1_1[[#This Row],[Joining_Date]],"yyyy") -> 2020 | J25: Active | K25: =IF(Table1_1[[#This Row],[Status]]="Exited",1,0) -> 0 | L25: =IF(Table1_1[[#This Row],[Status]]="Exited",0,1) -> 1 | M25: 967771 | N25: 3.6 | O25: Manager C | P25: 80.1 | Q25: =IF(AND(N25>4,P25>=75),"High", IF(AND(N25>2,N25<=4,P25>40,P25<=74),"Average","Low")) -> Low | T25: 4.1 | X25: 80.1
A26: EMP0025 | B26: Employee_25 | C26: HR | D26: Analyst | E26: Bangalore | F26: 2020-06-14 | G26: =TEXT(Table1_1[[#This Row],[Joining_Date]],"mmm") -> Jun | H26: =TEXT(Table1_1[[#This Row],[Joining_Date]],"yyyy") -> 2020 | I26: 44027 | J26: Exited | K26: =IF(Table1_1[[#This Row],[Status]]="Exited",1,0) -> 1 | L26: =IF(Table1_1[[#This Row],[Status]]="Exited",0,1) -> 0 | M26: 462719 | N26: 2.4 | O26: Manager C | P26: 96.6 | Q26: =IF(AND(N26>4,P26>=75),"High", IF(AND(N26>2,N26<=4,P26>40,P26<=74),"Average","Low")) -> Low | T26: 2 | X26: 96.6
A27: EMP0026 | B27: Employee_26 | C27: Sales | D27: Senior Executive | E27: Pune | F27: 2022-06-23 | G27: =TEXT(Table1_1[[#This Row],[Joining_Date]],"mmm") -> Jun | H27: =TEXT(Table1_1[[#This Row],[Joining_Date]],"yyyy") -> 2022 | I27: 44799 | J27: Exited | K27: =IF(Table1_1[[#This Row],[Status]]="Exited",1,0) -> 1 | L27: =IF(Table1_1[[#This Row],[Status]]="Exited",0,1) -> 0 | M27: 330780 | N27: 2.2 | O27: Manager A | P27: 95.9 | Q27: =IF(AND(N27>4,P27>=75),"High", IF(AND(N27>2,N27<=4,P27>40,P27<=74),"Average","Low")) -> Low | T27: 3.1 | X27: 95.9
A28: EMP0027 | B28: Employee_27 | C28: Sales | D28: Manager | E28: Pune | F28: 2019-11-07 | G28: =TEXT(Table1_1[[#This Row],[Joining_Date]],"mmm") -> Nov | H28: =TEXT(Table1_1[[#This Row],[Joining_Date]],"yyyy") -> 2019 | I28: 44431 | J28: Exited | K28: =IF(Table1_1[[#This Row],[Status]]="Exited",1,0) -> 1 | L28: =IF(Table1_1[[#This Row],[Status]]="Exited",0,1) -> 0 | M28: 516880 | N28: 3.9 | O28: Manager D | P28: 96.9 | Q28: =IF(AND(N28>4,P28>=75),"High", IF(AND(N28>2,N28<=4,P28>40,P28<=74),"Average","Low")) -> Low | T28: 3.8 | X28: 96.9
A29: EMP0028 | B29: Employee_28 | C29: HR | D29: Analyst | E29: Pune | F29: 2018-02-21 | G29: =TEXT(Table1_1[[#This Row],[Joining_Date]],"mmm") -> Feb | H29: =TEXT(Table1_1[[#This Row],[Joining_Date]],"yyyy") -> 2018 | I29: 44594 | J29: Exited | K29: =IF(Table1_1[[#This Row],[Status]]="Exited",1,0) -> 1 | L29: =IF(Table1_1[[#This Row],[Status]]="Exited",0,1) -> 0 | M29: 639166 | N29: 2.3 | O29: Manager D | P29: 75.2 | Q29: =IF(AND(N29>4,P29>=75),"High", IF(AND(N29>2,N29<=4,P29>40,P29<=74),"Average","Low")) -> Low | T29: 2.6 | X29: 75.2
A30: EMP0029 | B30: Employee_29 | C30: HR | D30: Senior Executive | E30: Mumbai | F30: 2024-02-19 | G30: =TEXT(Table1_1[[#This Row],[Joining_Date]],"mmm") -> Feb | H30: =TEXT(Table1_1[[#This Row],[Joining_Date]],"yyyy") -> 2024 | J30: Active | K30: =IF(Table1_1[[#This Row],[Status]]="Exited",1,0) -> 0 | L30: =IF(Table1_1[[#This Row],[Status]]="Exited",0,1) -> 1 | M30: 944641 | N30: 2.8 | O30: Manager C | P30: 99.6 | Q30: =IF(AND(N30>4,P30>=75),"High", IF(AND(N30>2,N30<=4,P30>40,P30<=74),"Average","Low")) -> Low | T30: 4.2 | X30: 99.6
A31: EMP0030 | B31: Employee_30 | C31: IT | D31: Manager | E31: Mumbai | F31: 2019-10-18 | G31: =TEXT(Table1_1[[#This Row],[Joining_Date]],"mmm") -> Oct | H31: =TEXT(Table1_1[[#This Row],[Joining_Date]],"yyyy") -> 2019 | I31: 43881 | J31: Exited | K31: =IF(Table1_1[[#This Row],[Status]]="Exited",1,0) -> 1 | L31: =IF(Table1_1[[#This Row],[Status]]="Exited",0,1) -> 0 | M31: 1138812 | N31: 5 | O31: Manager D | P31: 87.4 | Q31: =IF(AND(N31>4,P31>=75),"High", IF(AND(N31>2,N31<=4,P31>40,P31<=74),"Average","Low")) -> High | T31: 4 | X31: 87.4
A32: EMP0031 | B32: Employee_31 | C32: Finance | D32: Executive | E32: Pune | F32: 2024-10-18 | G32: =TEXT(Table1_1[[#This Row],[Joining_Date]],"mmm") -> Oct | H32: =TEXT(Table1_1[[#This Row],[Joining_Date]],"yyyy") -> 2024 | J32: Active | K32: =IF(Table1_1[[#This Row],[Status]]="Exited",1,0) -> 0 | L32: =IF(Table1_1[[#This Row],[Status]]="Exited",0,1) -> 1 | M32: 948550 | N32: 4.4 | O32: Manager C | P32: 99.3 | Q32: =IF(AND(N32>4,P32>=75),"High", IF(AND(N32>2,N32<=4,P32>40,P32<=74),"Average","Low")) -> High | T32: 3 | X32: 99.3
A33: EMP0032 | B33: Employee_32 | C33: Sales | D33: Executive | E33: Nagpur | F33: 2019-12-23 | G33: =TEXT(Table1_1[[#This Row],[Joining_Date]],"mmm") -> Dec | H33: =TEXT(Table1_1[[#This Row],[Joining_Date]],"yyyy") -> 2019 | I33: 44550 | J33: Exited | K33: =IF(Table1_1[[#This Row],[Status]]="Exited",1,0) -> 1 | L33: =IF(Table1_1[[#This Row],[Status]]="Exited",0,1) -> 0 | M33: 843035 | N33: 4.7 | O33: Manager A | P33: 79.8 | Q33: =IF(AND(N33>4,P33>=75),"High", IF(AND(N33>2,N33<=4,P33>40,P33<=74),"Average","Low")) -> High | X33: 98.7
A34: EMP0033 | B34: Employee_33 | C34: IT | D34: Manager | E34: Bangalore | F34: 2021-10-29 | G34: =TEXT(Table1_1[[#This Row],[Joining_Date]],"mmm") -> Oct | H34: =TEXT(Table1_1[[#This Row],[Joining_Date]],"yyyy") -> 2021 | I34: 45462 | J34: Exited | K34: =IF(Table1_1[[#This Row],[Status]]="Exited",1,0) -> 1 | L34: =IF(Table1_1[[#This Row],[Status]]="Exited",0,1) -> 0 | M34: 742532 | N34: 4.3 | O34: Manager D | P34: 98.7 | Q34: =IF(AND(N34>4,P34>=75),"High", IF(AND(N34>2,N34<=4,P34>40,P34<=74),"Average","Low")) -> High | X34: 86.9
A35: EMP0034 | B35: Employee_34 | C35: Operations | D35: Analyst | E35: Mumbai | F35: 2023-06-17 | G35: =TEXT(Table1_1[[#This Row],[Joining_Date]],"mmm") -> Jun | H35: =TEXT(Table1_1[[#This Row],[Joining_Date]],"yyyy") -> 2023 | I35: 45978 | J35: Exited | K35: =IF(Table1_1[[#This Row],[Status]]="Exited",1,0) -> 1 | L35: =IF(Table1_1[[#This Row],[Status]]="Exited",0,1) -> 0 | M35: 413138 | N35: 4.1 | O35: Manager B | P35: 86.9 | Q35: =IF(AND(N35>4,P35>=75),"High", IF(AND(N35>2,N35<=4,P35>40,P35<=74),"Average","Low")) -> High | X35: 80.6
A36: EMP0035 | B36: Employee_35 | C36: HR | D36: Senior Executive | E36: Pune | F36: 2021-07-02 | G36: =TEXT(Table1_1[[#This Row],[Joining_Date]],"mmm") -> Jul | H36: =TEXT(Table1_1[[#This Row],[Joining_Date]],"yyyy") -> 2021 | J36: Active | K36: =IF(Table1_1[[#This Row],[Status]]="Exited",1,0) -> 0 | L36: =IF(Table1_1[[#This Row],[Status]]="Exited",0,1) -> 1 | M36: 327661 | N36: 2.1 | O36: Manager A | P36: 80.6 | Q36: =IF(AND(N36>4,P36>=75),"High", IF(AND(N36>2,N36<=4,P36>40,P36<=74),"Average","Low")) -> Low | X36: 83
A37: EMP0036 | B37: Employee_36 | C37: Finance | D37: Executive | E37: Nagpur | F37: 2021-11-29 | G37: =TEXT(Table1_1[[#This Row],[Joining_Date]],"mmm") -> Nov | H37: =TEXT(Table1_1[[#This Row],[Joining_Date]],"yyyy") -> 2021 | I37: 45799 | J37: Exited | K37: =IF(Table1_1[[#This Row],[Status]]="Exited",1,0) -> 1 | L37: =IF(Table1_1[[#This Row],[Status]]="Exited",0,1) -> 0 | M37: 959364 | N37: 3.9 | O37: Manager D | P37: 83 | Q37: =IF(AND(N37>4,P37>=75),"High", IF(AND(N37>2,N37<=4,P37>40,P37<=74),"Average","Low")) -> Low | X37: 97.5
A38: EMP0037 | B38: Employee_37 | C38: HR | D38: Manager | E38: Nagpur | F38: 2021-06-29 | G38: =TEXT(Table1_1[[#This Row],[Joining_Date]],"mmm") -> Jun | H38: =TEXT(Table1_1[[#This Row],[Joining_Date]],"yyyy") -> 2021 | I38: 45250 | J38: Exited | K38: =IF(Table1_1[[#This Row],[Status]]="Exited",1,0) -> 1 | L38: =IF(Table1_1[[#This Row],[Status]]="Exited",0,1) -> 0 | M38: 874828 | N38: 2.8 | O38: Manager A | P38: 86.9 | Q38: =IF(AND(N38>4,P38>=75),"High", IF(AND(N38>2,N38<=4,P38>40,P38<=74),"Average","Low")) -> Low | X38: 96
A39: EMP0038 | B39: Employee_38 | C39: Operations | D39: Manager | E39: Nagpur | F39: 2021-06-10 | G39: =TEXT(Table1_1[[#This Row],[Joining_Date]],"mmm") -> Jun | H39: =TEXT(Table1_1[[#This Row],[Joining_Date]],"yyyy") -> 2021 | J39: Active | K39: =IF(Table1_1[[#This Row],[Status]]="Exited",1,0) -> 0 | L39: =IF(Table1_1[[#This Row],[Status]]="Exited",0,1) -> 1 | M39: 973248 | N39: 2 | O39: Manager B | P39: 97.5 | Q39: =IF(AND(N39>4,P39>=75),"High", IF(AND(N39>2,N39<=4,P39>40,P39<=74),"Average","Low")) -> Low | X39: 82.8
A40: EMP0039 | B40: Employee_39 | C40: Operations | D40: Senior Executive | E40: Pune | F40: 2021-02-10 | G40: =TEXT(Table1_1[[#This Row],[Joining_Date]],"mmm") -> Feb | H40: =TEXT(Table1_1[[#This Row],[Joining_Date]],"yyyy") -> 2021 | J40: Active | K40: =IF(Table1_1[[#This Row],[Status]]="Exited",1,0) -> 0 | L40: =IF(Table1_1[[#This Row],[Status]]="Exited",0,1) -> 1 | M40: 457965 | N40: 2.2 | O40: Manager D | P40: 97.5 | Q40: =IF(AND(N40>4,P40>=75),"High", IF(AND(N40>2,N40<=4,P40>40,P40<=74),"Average","Low")) -> Low | X40: 92.4
...
